Workbook
Name Utility: MasterOfficers!$S$3:$S$552
Name Minimum: Settings!$E$4:$E$39
Name Utility: MasterTech!$T$3:$T$200
Name Short: Settings!$D$4:$D$39

Sheet Infos - Start Here!
G2: 1.4-RC M86 | H2: =CONCATENATE("RC - Release Candidate",REPT(" · β",200)) -> RC - Release Candidate · β · β · β · β · β · β · β · β · β · β · β · β · β · β · β · β · β · β · β · β · β · β · β · β · β · β · β · β · β · β · β · β · β · β · β · β · β · β · β · β · β · β · β · β · β · β · β · β · β · β · β · β · β · β · β · β · β · β · β · β · β · β · β · β · β · β · β · β · β · β · β · β · β · β · β · β · β · β · β · β · β · β · β · β · β · β · β · β · β · β · β · β · β · β · β · β · β · β · β · β · β · β · β · β · β · β · β · β · β · β · β · β · β · β · β · β · β · β · β · β · β · β · β · β · β · β · β · β · β · β · β · β · β · β · β · β · β · β · β · β · β · β · β · β · β · β · β · β · β · β · β · β · β · β · β · β · β · β · β · β · β · β · β · β · β · β · β · β · β · β · β · β · β · β · β · β · β · β · β · β · β · β · β · β · β · β · β · β · β · β · β · β · β · β · β · β · β · β · β · β
D4: This spreadsheet attempts to tell you where officer & tech abilities work and where they don't.
E7: ➤ The titles are links to the correct tab.
B8: Join us
D9: ➤ Crew - Does it work? | E9: Build a crew from the captain through below decks to see where those abilities work
D11: ➤ officers search | E11: Select your target, and get a compact list with only applicable officer abilities.
D13: ➤ Sourcing Guide | E13: Imported from Officer Sourcing & Tiering Guide. Available sourcing fixed at ops 70 for simplicity
B14: Try it Yourself
B15: Make A Copy | D15: ➤ FT & CT search | E15: Select your target, and get a compact list with only applicable officer abilities.
D19: ➤ Glossary | E19: Definitions for game code text | I19: ➤ Spocks.club | J19: Powerful tools and calculators that use your game's inventory and buffs to show accurate read outs.
D21: ➤ Officers Compact view | E21: List of ALL officers & all potential targets. Use CTRL+F to check a specific officer
I22: ➤ Officer Tool & Discord | J22: Officer tool combines pre-set crews, ATA planning, buff calculations, and a battle log parcer.
B23: 45663 | D23: ➤ Officers Master Table | E23: Lists all known and exported information about abilities, their values, triggers, conditions, etc.
D25: ➤ Tech Master Table | E25: Lists all known and exported information about abilities, their values, triggers, conditions, etc. | I25: ➤ Charts Index | J25: List of all spreadsheets and charts made by JulesVern, Quasel and BlueMandalorian
D29: Want to dive even deeper? | E29: Create a copy of this sheets to use the tools. | K29: If the definition isn't here, try the ➤ GLOSSARY
D31: ➤ Hidden Tabs | E31: Many tabs are hidden as they serve as intermediate tables or calculations. Others are half-baked ideas. Manipulate @ your own risk. | I31: ✅ Ability works | K31: OA Officer Ability
I32: ✴️ Ability works, if all conditions are met
K33: CM Captain's Manuever
I34: ➖ Ability doesn't work
D35: Caveats / Trick | I35: Quick Legend | K35: BDA Below Deck ability
D37: ➤ Mission Boss | E37: Can have a Faction ID, might affect some officers
I38: Common | J38: Rarty of Officer
D39: ➤ Distraction FREE Editor | E39: Link to view the sheet in a minimal Interface | I39: Uncommon
I40: Rare
I41: Epic
D43: =CONCATENATE("RC - Release Candidate",REPT(" · β",200)) -> RC - Release Candidate · β · β · β · β · β · β · β · β · β · β · β · β · β · β · β · β · β · β · β · β · β · β · β · β · β · β · β · β · β · β · β · β · β · β · β · β · β · β · β · β · β · β · β · β · β · β · β · β · β · β · β · β · β · β · β · β · β · β · β · β · β · β · β · β · β · β · β · β · β · β · β · β · β · β · β · β · β · β · β · β · β · β · β · β · β · β · β · β · β · β · β · β · β · β · β · β · β · β · β · β · β · β · β · β · β · β · β · β · β · β · β · β · β · β · β · β · β · β · β · β · β · β · β · β · β · β · β · β · β · β · β · β · β · β · β · β · β · β · β · β · β · β · β · β · β · β · β · β · β · β · β · β · β · β · β · β · β · β · β · β · β · β · β · β · β · β · β · β · β · β · β · β · β · β · β · β · β · β · β · β · β · β · β · β · β · β · β · β · β · β · β · β · β · β · β · β · β · β · β · β

Sheet Crew - Does it work
G2: ='Infos - Start Here!'!G2 -> 1.4-RC M86 | H2: =CONCATENATE("RC - Release Candidate",REPT(" · β",200)) -> RC - Release Candidate · β · β · β · β · β · β · β · β · β · β · β · β · β · β · β · β · β · β · β · β · β · β · β · β · β · β · β · β · β · β · β · β · β · β · β · β · β · β · β · β · β · β · β · β · β · β · β · β · β · β · β · β · β · β · β · β · β · β · β · β · β · β · β · β · β · β · β · β · β · β · β · β · β · β · β · β · β · β · β · β · β · β · β · β · β · β · β · β · β · β · β · β · β · β · β · β · β · β · β · β · β · β · β · β · β · β · β · β · β · β · β · β · β · β · β · β · β · β · β · β · β · β · β · β · β · β · β · β · β · β · β · β · β · β · β · β · β · β · β · β · β · β · β · β · β · β · β · β · β · β · β · β · β · β · β · β · β · β · β · β · β · β · β · β · β · β · β · β · β · β · β · β · β · β · β · β · β · β · β · β · β · β · β · β · β · β · β · β · β · β · β · β · β · β · β · β · β · β · β · β
D4: Does this crew & tech work? | G4: Try it Yourself Make a Copy
J6: {=IFNA( XLOOKUP(J$10,LCARS_Tech[TechName],LCARS_Tech[Art]), "")} | K6: {=IFNA( XLOOKUP(K$10,LCARS_Tech[TechName],LCARS_Tech[Art]), "")}
C7: ᐅ | D7: 1 - Choose your Target | E7: PvP Station
E9: {=IFNA( XLOOKUP(E$12,LCARS_Off[OfficerName],LCARS_Off[Art]), "")} | F9: {=IFNA( XLOOKUP(F$12,LCARS_Off[OfficerName],LCARS_Off[Art]), "")} | G9: {=IFNA( XLOOKUP(G$12,LCARS_Off[OfficerName],LCARS_Off[Art]), "")}
H10: ᐅ | I10: Select your tech: | J10: [PRO] M-5 Multitronic Unit | K10: Mark VI Photon Torpedo
I11: Ability 1 | J11: =IFERROR(__xludf.DUMMYFUNCTION("FILTER( FILTER(LCARS_Tech[#ALL] , CONDITION_ONE_OF_RANGE( LCARS_Tech[#HEADERS] , E7)), CONDITION_ONE_OF_RANGE( LCARS_Tech[[#ALL],[TechName]] , J10) )"),"➖") -> ➖ | K11: =IFERROR(__xludf.DUMMYFUNCTION("FILTER( FILTER(LCARS_Tech[#ALL] , CONDITION_ONE_OF_RANGE( LCARS_Tech[#HEADERS] , E7)), CONDITION_ONE_OF_RANGE( LCARS_Tech[[#ALL],[TechName]] , K10) )"),"➖") -> ➖
C12: ᐅ | D12: Select your bridge crew: | E12: SESKA | F12: NAGA DELVOS | G12: WOK SCOTTY | I12: Ability 2 | J12: =IFERROR(__xludf.DUMMYFUNCTION("""COMPUTED_VALUE"""),"➖") -> ➖ | K12: =IFERROR(__xludf.DUMMYFUNCTION("""COMPUTED_VALUE"""),"➖") -> ➖
D13: Captain Maneuver "CM" | F13: =IFERROR(__xludf.DUMMYFUNCTION("IFNA( FILTER( FILTER(LCARS_Off[#ALL] , CONDITION_ONE_OF_RANGE( LCARS_Off[#HEADERS] , $E$7)), CONDITION_ONE_OF_RANGE( LCARS_Off[[#ALL],[OfficerName]] ,F12)*( LCARS_Off[[#ALL],[AbilityType]] = ""CM"" ) ), ""⃠"" )"),"➖") -> ➖ | I13: Ability 3 | J13: =IFERROR(__xludf.DUMMYFUNCTION("""COMPUTED_VALUE"""),"➖") -> ➖ | K13: =IFERROR(__xludf.DUMMYFUNCTION("""COMPUTED_VALUE"""),"✅") -> ✅
D14: Officer Ability "OA" | E14: =IFERROR(__xludf.DUMMYFUNCTION("IFNA( FILTER( FILTER(LCARS_Off[#ALL] , CONDITION_ONE_OF_RANGE( LCARS_Off[#HEADERS] , $E$7)), CONDITION_ONE_OF_RANGE( LCARS_Off[[#ALL],[OfficerName]] ,E12)*( LCARS_Off[[#ALL],[AbilityType]] = ""OA"" ) ), ""➖"" )"),"➖") -> ➖ | F14: =IFERROR(__xludf.DUMMYFUNCTION("IFNA( FILTER( FILTER(LCARS_Off[#ALL] , CONDITION_ONE_OF_RANGE( LCARS_Off[#HEADERS] , $E$7)), CONDITION_ONE_OF_RANGE( LCARS_Off[[#ALL],[OfficerName]] ,F12)*( LCARS_Off[[#ALL],[AbilityType]] = ""OA"" ) ), ""➖"" )"),"➖") -> ➖ | G14: =IFERROR(__xludf.DUMMYFUNCTION("IFNA( FILTER( FILTER(LCARS_Off[#ALL] , CONDITION_ONE_OF_RANGE( LCARS_Off[#HEADERS] , $E$7)), CONDITION_ONE_OF_RANGE( LCARS_Off[[#ALL],[OfficerName]] ,G12)*( LCARS_Off[[#ALL],[AbilityType]] = ""OA"" ) ), ""➖"" )"),"➖") -> ➖ | I14: Ability 4 | J14: =IFERROR(__xludf.DUMMYFUNCTION("""COMPUTED_VALUE"""),"➖") -> ➖
E15: {=IFERROR(XLOOKUP(E$19,LCARS_Off[OfficerName],LCARS_Off[Art]), "")} | F15: {=IFERROR(XLOOKUP(F$19,LCARS_Off[OfficerName],LCARS_Off[Art]), "")} | G15: {=IFERROR(XLOOKUP(G$19,LCARS_Off[OfficerName],LCARS_Off[Art]), "")} | H15: {=IFERROR(XLOOKUP(H$19,LCARS_Off[OfficerName],LCARS_Off[Art]), "")} | I15: {=IFERROR(XLOOKUP(I$19,LCARS_Off[OfficerName],LCARS_Off[Art]), "")} | J15: {=IFERROR(XLOOKUP(J$19,LCARS_Off[OfficerName],LCARS_Off[Art]), "")} | K15: {=IFERROR(XLOOKUP(K$19,LCARS_Off[OfficerName],LCARS_Off[Art]), "")}
C19: ᐅ | D19: Select your lower deckers: | E19: SCOTTY | F19: B'ELANNA TORRES | G19: TMP NYOTA UHURA
D20: Below Deck Ability "BDA" | E20: =IFERROR(__xludf.DUMMYFUNCTION("IFNA( FILTER( FILTER(LCARS_Off[#ALL] , CONDITION_ONE_OF_RANGE( LCARS_Off[#HEADERS] , $E$7)), CONDITION_ONE_OF_RANGE( LCARS_Off[[#ALL],[OfficerName]] ,E19)*( LCARS_Off[[#ALL],[AbilityType]] = ""BDA"" ) ), ""⃠"" )"),"⃠") -> ⃠ | F20: =IFERROR(__xludf.DUMMYFUNCTION("IFNA( FILTER( FILTER(LCARS_Off[#ALL] , CONDITION_ONE_OF_RANGE( LCARS_Off[#HEADERS] , $E$7)), CONDITION_ONE_OF_RANGE( LCARS_Off[[#ALL],[OfficerName]] ,F19)*( LCARS_Off[[#ALL],[AbilityType]] = ""BDA"" ) ), ""⃠"" )"),"➖") -> ➖ | G20: =IFERROR(__xludf.DUMMYFUNCTION("IFNA( FILTER( FILTER(LCARS_Off[#ALL] , CONDITION_ONE_OF_RANGE( LCARS_Off[#HEADERS] , $E$7)), CONDITION_ONE_OF_RANGE( LCARS_Off[[#ALL],[OfficerName]] ,G19)*( LCARS_Off[[#ALL],[AbilityType]] = ""BDA"" ) ), ""⃠"" )"),"➖") -> ➖ | H20: =IFERROR(__xludf.DUMMYFUNCTION("IFNA( FILTER( FILTER(LCARS_Off[#ALL] , CONDITION_ONE_OF_RANGE( LCARS_Off[#HEADERS] , $E$7)), CONDITION_ONE_OF_RANGE( LCARS_Off[[#ALL],[OfficerName]] ,H19)*( LCARS_Off[[#ALL],[AbilityType]] = ""BDA"" ) ), ""⃠"" )"),"⃠") -> ⃠ | I20: =IFERROR(__xludf.DUMMYFUNCTION("IFNA( FILTER( FILTER(LCARS_Off[#ALL] , CONDITION_ONE_OF_RANGE( LCARS_Off[#HEADERS] , $E$7)), CONDITION_ONE_OF_RANGE( LCARS_Off[[#ALL],[OfficerName]] ,I19)*( LCARS_Off[[#ALL],[AbilityType]] = ""BDA"" ) ), ""⃠"" )"),"⃠") -> ⃠ | J20: =IFERROR(__xludf.DUMMYFUNCTION("IFNA( FILTER( FILTER(LCARS_Off[#ALL] , CONDITION_ONE_OF_RANGE( LCARS_Off[#HEADERS] , $E$7)), CONDITION_ONE_OF_RANGE( LCARS_Off[[#ALL],[OfficerName]] ,J19)*( LCARS_Off[[#ALL],[AbilityType]] = ""BDA"" ) ), ""⃠"" )"),"⃠") -> ⃠ | K20: =IFERROR(__xludf.DUMMYFUNCTION("IFNA( FILTER( FILTER(LCARS_Off[#ALL] , CONDITION_ONE_OF_RANGE( LCARS_Off[#HEADERS] , $E$7)), CONDITION_ONE_OF_RANGE( LCARS_Off[[#ALL],[OfficerName]] ,K19)*( LCARS_Off[[#ALL],[AbilityType]] = ""BDA"" ) ), ""⃠"" )"),"⃠") -> ⃠
B24: ='Infos - Start Here!'!B23 -> 45663 | C24: ᐅ | D24: ="Target: " & E7 -> Target: PvP Station | F24: Ability Description | J24: Quick Legend
D25: Captain Maneuver "CM" | E25: =IFERROR(__xludf.DUMMYFUNCTION("IFNA( FILTER( FILTER(LCARS_Off[#ALL] , CONDITION_ONE_OF_RANGE( LCARS_Off[#HEADERS] , settings[DoesItWork])), CONDITION_ONE_OF_RANGE( LCARS_Off[[#ALL],[OfficerName]] ,F12)*( LCARS_Off[[#ALL],[AbilityType]] = ""CM"" ) ), Transpose({F12;F13}))"),"NAGA DELVOS") -> NAGA DELVOS | F25: =IFERROR(__xludf.DUMMYFUNCTION("""COMPUTED_VALUE"""),"Increases the Cost Efficiency of the Borg Cube's Transwarp Jump by X.") -> Increases the Cost Efficiency of the Borg Cube's Transwarp Jump by X. | I25: =IFERROR(__xludf.DUMMYFUNCTION("IFNA( FILTER( FILTER(LCARS_Off[#ALL] , CONDITION_ONE_OF_RANGE( LCARS_Off[#HEADERS] , $E$7)), CONDITION_ONE_OF_RANGE( LCARS_Off[[#ALL],[OfficerName]] ,E25)*( LCARS_Off[[#ALL],[AbilityType]] = ""CM"" ) ), ""⃠"" )")," ➖") -> ➖ | J25: ✅ | K25: Ability works
D26: Officer Ability "OA" | E26: =IFERROR(__xludf.DUMMYFUNCTION("FILTER( FILTER(LCARS_Off[#ALL] , CONDITION_ONE_OF_RANGE( LCARS_Off[#HEADERS] , settings[DoesItWork])), CONDITION_ONE_OF_RANGE( LCARS_Off[[#ALL],[OfficerName]] ,E12:G12)*( LCARS_Off[[#ALL],[AbilityType]] = ""OA"" ) )"),"NAGA DELVOS") -> NAGA DELVOS | F26: =IFERROR(__xludf.DUMMYFUNCTION("""COMPUTED_VALUE"""),"Increases the base damage of the Borg Cube's Cutting Beam against players by X (X at rank X).") -> Increases the base damage of the Borg Cube's Cutting Beam against players by X (X at rank X). | I26: =IFERROR(__xludf.DUMMYFUNCTION("IFNA( FILTER( FILTER(LCARS_Off[#ALL] , CONDITION_ONE_OF_RANGE( LCARS_Off[#HEADERS] , $E$7)), CONDITION_ONE_OF_RANGE( LCARS_Off[[#ALL],[OfficerName]] ,E26)*( LCARS_Off[[#ALL],[AbilityType]] = ""OA"" ) ), ""➖"" )")," ➖") -> ➖ | J26: ✴️ | K26: Ability works, if all conditions are met
E27: =IFERROR(__xludf.DUMMYFUNCTION("""COMPUTED_VALUE"""),"SESKA") -> SESKA | F27: =IFERROR(__xludf.DUMMYFUNCTION("""COMPUTED_VALUE"""),"Restores the Shield Health of your ship every round by X (X at rank X) when fighting hostiles.") -> Restores the Shield Health of your ship every round by X (X at rank X) when fighting hostiles. | I27: =IFERROR(__xludf.DUMMYFUNCTION("IFNA( FILTER( FILTER(LCARS_Off[#ALL] , CONDITION_ONE_OF_RANGE( LCARS_Off[#HEADERS] , $E$7)), CONDITION_ONE_OF_RANGE( LCARS_Off[[#ALL],[OfficerName]] ,E27)*( LCARS_Off[[#ALL],[AbilityType]] = ""OA"" ) ), ""➖"" )")," ➖") -> ➖ | J27: ⃠ | K27: No CM or BDA
E28: =IFERROR(__xludf.DUMMYFUNCTION("""COMPUTED_VALUE"""),"WOK SCOTTY") -> WOK SCOTTY | F28: =IFERROR(__xludf.DUMMYFUNCTION("""COMPUTED_VALUE"""),"WOK Montgomery Scott increases loot gained from Armadas by X (X at rank X).") -> WOK Montgomery Scott increases loot gained from Armadas by X (X at rank X). | I28: =IFERROR(__xludf.DUMMYFUNCTION("IFNA( FILTER( FILTER(LCARS_Off[#ALL] , CONDITION_ONE_OF_RANGE( LCARS_Off[#HEADERS] , $E$7)), CONDITION_ONE_OF_RANGE( LCARS_Off[[#ALL],[OfficerName]] ,E28)*( LCARS_Off[[#ALL],[AbilityType]] = ""OA"" ) ), ""➖"" )")," ➖") -> ➖ | J28: ➖ | K28: Does not work against the target
D29: Below Deck Ability "BDA" | E29: =IFERROR(__xludf.DUMMYFUNCTION("IFNA( FILTER( FILTER(LCARS_Off[#ALL] , CONDITION_ONE_OF_RANGE( LCARS_Off[#HEADERS] , settings[DoesItWork])), CONDITION_ONE_OF_RANGE( LCARS_Off[[#ALL],[OfficerName]] , E19:K19)*( LCARS_Off[[#ALL],[AbilityType]] = ""BDA"" ) ), ""➖"")"),"B'ELANNA TORRES") -> B'ELANNA TORRES | F29: =IFERROR(__xludf.DUMMYFUNCTION("""COMPUTED_VALUE"""),"X chance each round to apply Hull Breach to non-Player hostiles or Armada for 1 round.") -> X chance each round to apply Hull Breach to non-Player hostiles or Armada for 1 round. | I29: =IFERROR(__xludf.DUMMYFUNCTION("IFNA( FILTER( FILTER(LCARS_Off[#ALL] , CONDITION_ONE_OF_RANGE( LCARS_Off[#HEADERS] , $E$7)), CONDITION_ONE_OF_RANGE( LCARS_Off[[#ALL],[OfficerName]] ,E29)*( LCARS_Off[[#ALL],[AbilityType]] = ""BDA"" ) ), "" ⃠"" )")," ➖") -> ➖ | J29: OA | K29: Officer Ability
E30: =IFERROR(__xludf.DUMMYFUNCTION("""COMPUTED_VALUE"""),"TMP NYOTA UHURA") -> TMP NYOTA UHURA | F30: =IFERROR(__xludf.DUMMYFUNCTION("""COMPUTED_VALUE"""),"TMP Nyota Uhura increases your ship's Isolytic Cascade Damage by X (X at rank X) when fighting non-Armada Hostiles, Outposts, or Retaliation Hostiles.") -> TMP Nyota Uhura increases your ship's Isolytic Cascade Damage by X (X at rank X) when fighting non-Armada Hostiles, Outposts, or Retaliation Hostiles. | I30: =IFERROR(__xludf.DUMMYFUNCTION("IFNA( FILTER( FILTER(LCARS_Off[#ALL] , CONDITION_ONE_OF_RANGE( LCARS_Off[#HEADERS] , $E$7)), CONDITION_ONE_OF_RANGE( LCARS_Off[[#ALL],[OfficerName]] ,E30)*( LCARS_Off[[#ALL],[AbilityType]] = ""BDA"" ) ), "" ⃠"" )")," ➖") -> ➖ | J30: CM | K30: Captain's Manuever
I31: =IFERROR(__xludf.DUMMYFUNCTION("IFNA( FILTER( FILTER(LCARS_Off[#ALL] , CONDITION_ONE_OF_RANGE( LCARS_Off[#HEADERS] , $E$7)), CONDITION_ONE_OF_RANGE( LCARS_Off[[#ALL],[OfficerName]] ,E31)*( LCARS_Off[[#ALL],[AbilityType]] = ""BDA"" ) ), "" ⃠"" )")," ⃠") -> ⃠ | J31: BDA | K31: Below Deck Ability
I32: =IFERROR(__xludf.DUMMYFUNCTION("IFNA( FILTER( FILTER(LCARS_Off[#ALL] , CONDITION_ONE_OF_RANGE( LCARS_Off[#HEADERS] , $E$7)), CONDITION_ONE_OF_RANGE( LCARS_Off[[#ALL],[OfficerName]] ,E32)*( LCARS_Off[[#ALL],[AbilityType]] = ""BDA"" ) ), "" ⃠"" )")," ⃠") -> ⃠ | J32: If the definition isn't here, try the Glossary.
I33: =IFERROR(__xludf.DUMMYFUNCTION("IFNA( FILTER( FILTER(LCARS_Off[#ALL] , CONDITION_ONE_OF_RANGE( LCARS_Off[#HEADERS] , $E$7)), CONDITION_ONE_OF_RANGE( LCARS_Off[[#ALL],[OfficerName]] ,E33)*( LCARS_Off[[#ALL],[AbilityType]] = ""BDA"" ) ), "" ⃠"" )")," ⃠") -> ⃠
I34: =IFERROR(__xludf.DUMMYFUNCTION("IFNA( FILTER( FILTER(LCARS_Off[#ALL] , CONDITION_ONE_OF_RANGE( LCARS_Off[#HEADERS] , $E$7)), CONDITION_ONE_OF_RANGE( LCARS_Off[[#ALL],[OfficerName]] ,E34)*( LCARS_Off[[#ALL],[AbilityType]] = ""BDA"" ) ), "" ⃠"" )")," ⃠") -> ⃠
I35: =IFERROR(__xludf.DUMMYFUNCTION("IFNA( FILTER( FILTER(LCARS_Off[#ALL] , CONDITION_ONE_OF_RANGE( LCARS_Off[#HEADERS] , $E$7)), CONDITION_ONE_OF_RANGE( LCARS_Off[[#ALL],[OfficerName]] ,E35)*( LCARS_Off[[#ALL],[AbilityType]] = ""BDA"" ) ), "" ⃠"" )")," ⃠") -> ⃠ | J35: Try it Yourself
D36: Forbidden Tech "FT" | E36: =IFERROR(__xludf.DUMMYFUNCTION("FILTER( FILTER(LCARS_Tech[#ALL] , CONDITION_ONE_OF_RANGE( LCARS_Tech[#HEADERS] , settings[DoesItWork])), CONDITION_ONE_OF_RANGE( LCARS_Tech[[#ALL],[TechName]] , J10) )"),"[PRO] M-5 Multitronic Unit") -> [PRO] M-5 Multitronic Unit | F36: =IFERROR(__xludf.DUMMYFUNCTION("""COMPUTED_VALUE"""),"Increases Critical Hit Chance against Outposts by X.") -> Increases Critical Hit Chance against Outposts by X. | I36: =IFERROR(__xludf.DUMMYFUNCTION("FILTER( FILTER(LCARS_Tech[#ALL] , CONDITION_ONE_OF_RANGE( LCARS_Tech[#HEADERS] , E7)), CONDITION_ONE_OF_RANGE( LCARS_Tech[[#ALL],[TechName]] , J10) )")," ➖") -> ➖ | J36: Make a Copy
F37: =IFERROR(__xludf.DUMMYFUNCTION("""COMPUTED_VALUE"""),"Increase all Mitigation stats against Outposts and Outpost Retaliation Hostiles by X.") -> Increase all Mitigation stats against Outposts and Outpost Retaliation Hostiles by X. | I37: =IFERROR(__xludf.DUMMYFUNCTION("""COMPUTED_VALUE""")," ➖") -> ➖
F38: =IFERROR(__xludf.DUMMYFUNCTION("""COMPUTED_VALUE"""),"Increases Base Damage against Borg Outpost Retaliation Hostiles by X.") -> Increases Base Damage against Borg Outpost Retaliation Hostiles by X. | I38: =IFERROR(__xludf.DUMMYFUNCTION("""COMPUTED_VALUE""")," ➖") -> ➖ | J38: Join us on the official Discord Channel
F39: =IFERROR(__xludf.DUMMYFUNCTION("""COMPUTED_VALUE"""),"Increases Apex Barrier against Borg Outposts and Borg Outpost Retaliation Hostiles by X. Does not apply when Tal is assigned to the bridge.") -> Increases Apex Barrier against Borg Outposts and Borg Outpost Retaliation Hostiles by X. Does not apply when Tal is assigned to the bridge. | I39: =IFERROR(__xludf.DUMMYFUNCTION("""COMPUTED_VALUE""")," ➖") -> ➖ | J39: Official Tool Discord Server
D40: Chaos Tech "CT" | E40: =IFERROR(__xludf.DUMMYFUNCTION("FILTER( FILTER(LCARS_Tech[#ALL] , CONDITION_ONE_OF_RANGE( LCARS_Tech[#HEADERS] , settings[DoesItWork])), CONDITION_ONE_OF_RANGE( LCARS_Tech[[#ALL],[TechName]] , K10) )"),"Mark VI Photon Torpedo") -> Mark VI Photon Torpedo | F40: =IFERROR(__xludf.DUMMYFUNCTION("""COMPUTED_VALUE"""),"On round start, has a X chance to apply Hull Breach to [WOK] Hostiles for 3 rounds when commanding the U.S.S. Reliant.") -> On round start, has a X chance to apply Hull Breach to [WOK] Hostiles for 3 rounds when commanding the U.S.S. Reliant. | I40: =IFERROR(__xludf.DUMMYFUNCTION("FILTER( FILTER(LCARS_Tech[#ALL] , CONDITION_ONE_OF_RANGE( LCARS_Tech[#HEADERS] , E7)), CONDITION_ONE_OF_RANGE( LCARS_Tech[[#ALL],[TechName]] , K10) )")," ➖") -> ➖
F41: =IFERROR(__xludf.DUMMYFUNCTION("""COMPUTED_VALUE"""),"Increases Champion Trophy rewards from hostile chests by X of base value when commanding the U.S.S. Reliant.") -> Increases Champion Trophy rewards from hostile chests by X of base value when commanding the U.S.S. Reliant. | I41: =IFERROR(__xludf.DUMMYFUNCTION("""COMPUTED_VALUE""")," ➖") -> ➖
F42: =IFERROR(__xludf.DUMMYFUNCTION("""COMPUTED_VALUE"""),"Increases base Hull Health by X.") -> Increases base Hull Health by X. | I42: =IFERROR(__xludf.DUMMYFUNCTION("""COMPUTED_VALUE""")," ✅") -> ✅
C45: =CONCATENATE("RC - Release Candidate",REPT(" · β",200)) -> RC - Release Candidate · β · β · β · β · β · β · β · β · β · β · β · β · β · β · β · β · β · β · β · β · β · β · β · β · β · β · β · β · β · β · β · β · β · β · β · β · β · β · β · β · β · β · β · β · β · β · β · β · β · β · β · β · β · β · β · β · β · β · β · β · β · β · β · β · β · β · β · β · β · β · β · β · β · β · β · β · β · β · β · β · β · β · β · β · β · β · β · β · β · β · β · β · β · β · β · β · β · β · β · β · β · β · β · β · β · β · β · β · β · β · β · β · β · β · β · β · β · β · β · β · β · β · β · β · β · β · β · β · β · β · β · β · β · β · β · β · β · β · β · β · β · β · β · β · β · β · β · β · β · β · β · β · β · β · β · β · β · β · β · β · β · β · β · β · β · β · β · β · β · β · β · β · β · β · β · β · β · β · β · β · β · β · β · β · β · β · β · β · β · β · β · β · β · β · β · β · β · β · β · β

Sheet Officers - Search 
G2: ='Infos - Start Here!'!G2 -> 1.4-RC M86 | H2: =CONCATENATE("RC - Release Candidate",REPT(" · β",200)) -> RC - Release Candidate · β · β · β · β · β · β · β · β · β · β · β · β · β · β · β · β · β · β · β · β · β · β · β · β · β · β · β · β · β · β · β · β · β · β · β · β · β · β · β · β · β · β · β · β · β · β · β · β · β · β · β · β · β · β · β · β · β · β · β · β · β · β · β · β · β · β · β · β · β · β · β · β · β · β · β · β · β · β · β · β · β · β · β · β · β · β · β · β · β · β · β · β · β · β · β · β · β · β · β · β · β · β · β · β · β · β · β · β · β · β · β · β · β · β · β · β · β · β · β · β · β · β · β · β · β · β · β · β · β · β · β · β · β · β · β · β · β · β · β · β · β · β · β · β · β · β · β · β · β · β · β · β · β · β · β · β · β · β · β · β · β · β · β · β · β · β · β · β · β · β · β · β · β · β · β · β · β · β · β · β · β · β · β · β · β · β · β · β · β · β · β · β · β · β · β · β · β · β · β · β
D4: ᐅ | E4: PvP Station | H4: Select the Target | J4: Sort Order: Works, Conditional, Name ASC
D5: ᐅ | E5: BDA, CM, OA | H5: Select the Ability Type(s)
D6: ᐅ | H6: Search term e.g Hull Breach, Attack, State,…
D8: =IFERROR(__xludf.DUMMYFUNCTION("Query( FILTER( FILTER(LCARS_Off[#ALL] , CONDITION_ONE_OF_RANGE( LCARS_Off[#HEADERS] , settings[Minimum]) +(LCARS_Off[#HEADERS] = E4) ), ISNUMBER(SEARCH( E6, LCARS_Off[[#ALL],[Ability Description]])) + (LCARS_Off[[#ALL],[AbilityID]]=""AbilityID""), CONDITI"&"ON_ONE_OF_RANGE( LCARS_Off[[#ALL],[AbilityType]], SPLIT(E5, "", "", false, true)) + (LCARS_Off[[#ALL],[AbilityID]]=""AbilityID"") ) , ""SELECT * WHERE Col4 != '➖' ORDER BY Col4, Col2"",1 )")," Rarity") -> Rarity | E8: =IFERROR(__xludf.DUMMYFUNCTION("""COMPUTED_VALUE"""),"OfficerName") -> OfficerName | H8: =IFERROR(__xludf.DUMMYFUNCTION("""COMPUTED_VALUE"""),"Reason") -> Reason | I8: =IFERROR(__xludf.DUMMYFUNCTION("""COMPUTED_VALUE"""),"Ability Modifier") -> Ability Modifier | J8: =IFERROR(__xludf.DUMMYFUNCTION("""COMPUTED_VALUE"""),"Ability Description") -> Ability Description
D9: =IFERROR(__xludf.DUMMYFUNCTION("""COMPUTED_VALUE""")," U") -> U | E9: =IFERROR(__xludf.DUMMYFUNCTION("""COMPUTED_VALUE"""),"718") -> 718 | F9: =IFERROR(__xludf.DUMMYFUNCTION("""COMPUTED_VALUE"""),"CM") -> CM | G9: =IFERROR(__xludf.DUMMYFUNCTION("""COMPUTED_VALUE"""),"✅") -> ✅ | I9: =IFERROR(__xludf.DUMMYFUNCTION("""COMPUTED_VALUE"""),"CritChance") -> CritChance | J9: =IFERROR(__xludf.DUMMYFUNCTION("""COMPUTED_VALUE"""),"0718 Increases the Critical Hit Chances by X when defending the Station.") -> 0718 Increases the Critical Hit Chances by X when defending the Station.
D10: =IFERROR(__xludf.DUMMYFUNCTION("""COMPUTED_VALUE""")," U") -> U | E10: =IFERROR(__xludf.DUMMYFUNCTION("""COMPUTED_VALUE"""),"718") -> 718 | F10: =IFERROR(__xludf.DUMMYFUNCTION("""COMPUTED_VALUE"""),"OA") -> OA | G10: =IFERROR(__xludf.DUMMYFUNCTION("""COMPUTED_VALUE"""),"✅") -> ✅ | I10: =IFERROR(__xludf.DUMMYFUNCTION("""COMPUTED_VALUE"""),"OfficerStatDefense") -> OfficerStatDefense | J10: =IFERROR(__xludf.DUMMYFUNCTION("""COMPUTED_VALUE"""),"0718 increases the Defense of all Officers on the ship by X.") -> 0718 increases the Defense of all Officers on the ship by X.
D11: =IFERROR(__xludf.DUMMYFUNCTION("""COMPUTED_VALUE""")," U") -> U | E11: =IFERROR(__xludf.DUMMYFUNCTION("""COMPUTED_VALUE"""),"ARKADY") -> ARKADY | F11: =IFERROR(__xludf.DUMMYFUNCTION("""COMPUTED_VALUE"""),"CM") -> CM | G11: =IFERROR(__xludf.DUMMYFUNCTION("""COMPUTED_VALUE"""),"✅") -> ✅ | I11: =IFERROR(__xludf.DUMMYFUNCTION("""COMPUTED_VALUE"""),"AddState") -> AddState | J11: =IFERROR(__xludf.DUMMYFUNCTION("""COMPUTED_VALUE"""),"When the shield is depleted, Arkady has a X chance of inspiring Morale to the ship for 3 rounds.") -> When the shield is depleted, Arkady has a X chance of inspiring Morale to the ship for 3 rounds.
D12: =IFERROR(__xludf.DUMMYFUNCTION("""COMPUTED_VALUE""")," U") -> U | E12: =IFERROR(__xludf.DUMMYFUNCTION("""COMPUTED_VALUE"""),"ARKADY") -> ARKADY | F12: =IFERROR(__xludf.DUMMYFUNCTION("""COMPUTED_VALUE"""),"OA") -> OA | G12: =IFERROR(__xludf.DUMMYFUNCTION("""COMPUTED_VALUE"""),"✅") -> ✅ | I12: =IFERROR(__xludf.DUMMYFUNCTION("""COMPUTED_VALUE"""),"ShieldHPMax") -> ShieldHPMax | J12: =IFERROR(__xludf.DUMMYFUNCTION("""COMPUTED_VALUE"""),"Arkady increases the Shield Health of the ship by X.") -> Arkady increases the Shield Health of the ship by X.
D13: =IFERROR(__xludf.DUMMYFUNCTION("""COMPUTED_VALUE""")," R") -> R | E13: =IFERROR(__xludf.DUMMYFUNCTION("""COMPUTED_VALUE"""),"AZETBUR") -> AZETBUR | F13: =IFERROR(__xludf.DUMMYFUNCTION("""COMPUTED_VALUE"""),"OA") -> OA | G13: =IFERROR(__xludf.DUMMYFUNCTION("""COMPUTED_VALUE"""),"✅") -> ✅ | I13: =IFERROR(__xludf.DUMMYFUNCTION("""COMPUTED_VALUE"""),"ArmorPiercing") -> ArmorPiercing | J13: =IFERROR(__xludf.DUMMYFUNCTION("""COMPUTED_VALUE"""),"Every time the ship hits the opponent with a weapon attack, Azetbur increases the Armor Piercing of the ship by X. -- (Weapons with multiple shots will only trigger this ability once per attack.)") -> Every time the ship hits the opponent with a weapon attack, Azetbur increases the Armor Piercing of the ship by X. -- (Weapons with multiple shots will only trigger this ability once per attack.)
D14: =IFERROR(__xludf.DUMMYFUNCTION("""COMPUTED_VALUE""")," R") -> R | E14: =IFERROR(__xludf.DUMMYFUNCTION("""COMPUTED_VALUE"""),"BA'EL") -> BA'EL | F14: =IFERROR(__xludf.DUMMYFUNCTION("""COMPUTED_VALUE"""),"CM") -> CM | G14: =IFERROR(__xludf.DUMMYFUNCTION("""COMPUTED_VALUE"""),"✅") -> ✅ | I14: =IFERROR(__xludf.DUMMYFUNCTION("""COMPUTED_VALUE"""),"AllDamage") -> AllDamage | J14: =IFERROR(__xludf.DUMMYFUNCTION("""COMPUTED_VALUE"""),"Ba'el increases the ship's Weapon Damage by X.") -> Ba'el increases the ship's Weapon Damage by X.
D15: =IFERROR(__xludf.DUMMYFUNCTION("""COMPUTED_VALUE""")," R") -> R | E15: =IFERROR(__xludf.DUMMYFUNCTION("""COMPUTED_VALUE"""),"BA'EL") -> BA'EL | F15: =IFERROR(__xludf.DUMMYFUNCTION("""COMPUTED_VALUE"""),"OA") -> OA | G15: =IFERROR(__xludf.DUMMYFUNCTION("""COMPUTED_VALUE"""),"✅") -> ✅ | I15: =IFERROR(__xludf.DUMMYFUNCTION("""COMPUTED_VALUE"""),"ShipArmor") -> ShipArmor | J15: =IFERROR(__xludf.DUMMYFUNCTION("""COMPUTED_VALUE"""),"Ba'el increases the ship's Armor by X of total Crew Attack.") -> Ba'el increases the ship's Armor by X of total Crew Attack.
D16: =IFERROR(__xludf.DUMMYFUNCTION("""COMPUTED_VALUE""")," U") -> U | E16: =IFERROR(__xludf.DUMMYFUNCTION("""COMPUTED_VALUE"""),"BADGEY") -> BADGEY | F16: =IFERROR(__xludf.DUMMYFUNCTION("""COMPUTED_VALUE"""),"OA") -> OA | G16: =IFERROR(__xludf.DUMMYFUNCTION("""COMPUTED_VALUE"""),"✅") -> ✅ | I16: =IFERROR(__xludf.DUMMYFUNCTION("""COMPUTED_VALUE"""),"AllDefenses") -> AllDefenses | J16: =IFERROR(__xludf.DUMMYFUNCTION("""COMPUTED_VALUE"""),"Badgey decreases the Armor, Shield Deflection, and Dodge of enemy ships by X.") -> Badgey decreases the Armor, Shield Deflection, and Dodge of enemy ships by X.
D17: =IFERROR(__xludf.DUMMYFUNCTION("""COMPUTED_VALUE""")," U") -> U | E17: =IFERROR(__xludf.DUMMYFUNCTION("""COMPUTED_VALUE"""),"BADGEY") -> BADGEY | F17: =IFERROR(__xludf.DUMMYFUNCTION("""COMPUTED_VALUE"""),"BDA") -> BDA | G17: =IFERROR(__xludf.DUMMYFUNCTION("""COMPUTED_VALUE"""),"✅") -> ✅ | I17: =IFERROR(__xludf.DUMMYFUNCTION("""COMPUTED_VALUE"""),"AllPiercing") -> AllPiercing | J17: =IFERROR(__xludf.DUMMYFUNCTION("""COMPUTED_VALUE"""),"Badgey increases Armor Penetration, Shield Penetration, and Accuracy by X.") -> Badgey increases Armor Penetration, Shield Penetration, and Accuracy by X.
D18: =IFERROR(__xludf.DUMMYFUNCTION("""COMPUTED_VALUE""")," E") -> E | E18: =IFERROR(__xludf.DUMMYFUNCTION("""COMPUTED_VALUE"""),"BECKETT MARINER") -> BECKETT MARINER | F18: =IFERROR(__xludf.DUMMYFUNCTION("""COMPUTED_VALUE"""),"OA") -> OA | G18: =IFERROR(__xludf.DUMMYFUNCTION("""COMPUTED_VALUE"""),"✅") -> ✅ | I18: =IFERROR(__xludf.DUMMYFUNCTION("""COMPUTED_VALUE"""),"OfficerStatAttack") -> OfficerStatAttack | J18: =IFERROR(__xludf.DUMMYFUNCTION("""COMPUTED_VALUE"""),"Beckett Mariner increases the Attack of all Officers on the ship by X.") -> Beckett Mariner increases the Attack of all Officers on the ship by X.
D19: =IFERROR(__xludf.DUMMYFUNCTION("""COMPUTED_VALUE""")," E") -> E | E19: =IFERROR(__xludf.DUMMYFUNCTION("""COMPUTED_VALUE"""),"BECKETT MARINER") -> BECKETT MARINER | F19: =IFERROR(__xludf.DUMMYFUNCTION("""COMPUTED_VALUE"""),"BDA") -> BDA | G19: =IFERROR(__xludf.DUMMYFUNCTION("""COMPUTED_VALUE"""),"✅") -> ✅ | I19: =IFERROR(__xludf.DUMMYFUNCTION("""COMPUTED_VALUE"""),"AllDamage") -> AllDamage | J19: =IFERROR(__xludf.DUMMYFUNCTION("""COMPUTED_VALUE"""),"Beckett Mariner increases the ship's Weapon Damage by X.") -> Beckett Mariner increases the ship's Weapon Damage by X.
D20: =IFERROR(__xludf.DUMMYFUNCTION("""COMPUTED_VALUE""")," R") -> R | E20: =IFERROR(__xludf.DUMMYFUNCTION("""COMPUTED_VALUE"""),"BLACK OPS CHAPEL") -> BLACK OPS CHAPEL | F20: =IFERROR(__xludf.DUMMYFUNCTION("""COMPUTED_VALUE"""),"BDA") -> BDA | G20: =IFERROR(__xludf.DUMMYFUNCTION("""COMPUTED_VALUE"""),"✅") -> ✅ | I20: =IFERROR(__xludf.DUMMYFUNCTION("""COMPUTED_VALUE"""),"HullHPMax") -> HullHPMax | J20: =IFERROR(__xludf.DUMMYFUNCTION("""COMPUTED_VALUE"""),"SNW Black Ops Chapel increases the ship's base Hull Health by X (X at rank X).") -> SNW Black Ops Chapel increases the ship's base Hull Health by X (X at rank X).
D21: =IFERROR(__xludf.DUMMYFUNCTION("""COMPUTED_VALUE""")," R") -> R | E21: =IFERROR(__xludf.DUMMYFUNCTION("""COMPUTED_VALUE"""),"BRAD BOIMLER") -> BRAD BOIMLER | F21: =IFERROR(__xludf.DUMMYFUNCTION("""COMPUTED_VALUE"""),"OA") -> OA | G21: =IFERROR(__xludf.DUMMYFUNCTION("""COMPUTED_VALUE"""),"✅") -> ✅ | I21: =IFERROR(__xludf.DUMMYFUNCTION("""COMPUTED_VALUE"""),"AllPiercing") -> AllPiercing | J21: =IFERROR(__xludf.DUMMYFUNCTION("""COMPUTED_VALUE"""),"Brad Boimler increases Armor Piercing, Shield Piercing, and Accuracy by X.") -> Brad Boimler increases Armor Piercing, Shield Piercing, and Accuracy by X.
B22: ='Infos - Start Here!'!B22 | D22: =IFERROR(__xludf.DUMMYFUNCTION("""COMPUTED_VALUE""")," R") -> R | E22: =IFERROR(__xludf.DUMMYFUNCTION("""COMPUTED_VALUE"""),"BRAD BOIMLER") -> BRAD BOIMLER | F22: =IFERROR(__xludf.DUMMYFUNCTION("""COMPUTED_VALUE"""),"BDA") -> BDA | G22: =IFERROR(__xludf.DUMMYFUNCTION("""COMPUTED_VALUE"""),"✅") -> ✅ | I22: =IFERROR(__xludf.DUMMYFUNCTION("""COMPUTED_VALUE"""),"AllDefenses") -> AllDefenses | J22: =IFERROR(__xludf.DUMMYFUNCTION("""COMPUTED_VALUE"""),"Brad Boimler increases Armor, Shield Deflection, and Dodge by X.") -> Brad Boimler increases Armor, Shield Deflection, and Dodge by X.
D23: =IFERROR(__xludf.DUMMYFUNCTION("""COMPUTED_VALUE""")," C") -> C | E23: =IFERROR(__xludf.DUMMYFUNCTION("""COMPUTED_VALUE"""),"CADET KIRK") -> CADET KIRK | F23: =IFERROR(__xludf.DUMMYFUNCTION("""COMPUTED_VALUE"""),"CM") -> CM | G23: =IFERROR(__xludf.DUMMYFUNCTION("""COMPUTED_VALUE"""),"✅") -> ✅ | I23: =IFERROR(__xludf.DUMMYFUNCTION("""COMPUTED_VALUE"""),"OfficerStatAll") -> OfficerStatAll | J23: =IFERROR(__xludf.DUMMYFUNCTION("""COMPUTED_VALUE"""),"Cadet Kirk increases the Attack, Defense and Health of all Officers on the Bridge by X.") -> Cadet Kirk increases the Attack, Defense and Health of all Officers on the Bridge by X.
D24: =IFERROR(__xludf.DUMMYFUNCTION("""COMPUTED_VALUE""")," C") -> C | E24: =IFERROR(__xludf.DUMMYFUNCTION("""COMPUTED_VALUE"""),"CADET KIRK") -> CADET KIRK | F24: =IFERROR(__xludf.DUMMYFUNCTION("""COMPUTED_VALUE"""),"OA") -> OA | G24: =IFERROR(__xludf.DUMMYFUNCTION("""COMPUTED_VALUE"""),"✅") -> ✅ | I24: =IFERROR(__xludf.DUMMYFUNCTION("""COMPUTED_VALUE"""),"AllDamage") -> AllDamage | J24: =IFERROR(__xludf.DUMMYFUNCTION("""COMPUTED_VALUE"""),"Kirk increases the Weapon damage of the ship by X.") -> Kirk increases the Weapon damage of the ship by X.
D25: =IFERROR(__xludf.DUMMYFUNCTION("""COMPUTED_VALUE""")," C") -> C | E25: =IFERROR(__xludf.DUMMYFUNCTION("""COMPUTED_VALUE"""),"CADET MCCOY") -> CADET MCCOY | F25: =IFERROR(__xludf.DUMMYFUNCTION("""COMPUTED_VALUE"""),"CM") -> CM | G25: =IFERROR(__xludf.DUMMYFUNCTION("""COMPUTED_VALUE"""),"✅") -> ✅ | I25: =IFERROR(__xludf.DUMMYFUNCTION("""COMPUTED_VALUE"""),"OfficerStatHealth") -> OfficerStatHealth | J25: =IFERROR(__xludf.DUMMYFUNCTION("""COMPUTED_VALUE"""),"Cadet McCoy increases the Health of all Officers on the ship by X.") -> Cadet McCoy increases the Health of all Officers on the ship by X.
D26: =IFERROR(__xludf.DUMMYFUNCTION("""COMPUTED_VALUE""")," C") -> C | E26: =IFERROR(__xludf.DUMMYFUNCTION("""COMPUTED_VALUE"""),"CADET MCCOY") -> CADET MCCOY | F26: =IFERROR(__xludf.DUMMYFUNCTION("""COMPUTED_VALUE"""),"OA") -> OA | G26: =IFERROR(__xludf.DUMMYFUNCTION("""COMPUTED_VALUE"""),"✅") -> ✅ | I26: =IFERROR(__xludf.DUMMYFUNCTION("""COMPUTED_VALUE"""),"CptManeuverEffect") -> CptManeuverEffect | J26: =IFERROR(__xludf.DUMMYFUNCTION("""COMPUTED_VALUE"""),"During combat, Cadet McCoy increases the effectiveness of the Captain Maneuver by X.") -> During combat, Cadet McCoy increases the effectiveness of the Captain Maneuver by X.
D27: =IFERROR(__xludf.DUMMYFUNCTION("""COMPUTED_VALUE""")," C") -> C | E27: =IFERROR(__xludf.DUMMYFUNCTION("""COMPUTED_VALUE"""),"CADET SCOTTY") -> CADET SCOTTY | F27: =IFERROR(__xludf.DUMMYFUNCTION("""COMPUTED_VALUE"""),"CM") -> CM | G27: =IFERROR(__xludf.DUMMYFUNCTION("""COMPUTED_VALUE"""),"✅") -> ✅ | I27: =IFERROR(__xludf.DUMMYFUNCTION("""COMPUTED_VALUE"""),"HullHPMax") -> HullHPMax | J27: =IFERROR(__xludf.DUMMYFUNCTION("""COMPUTED_VALUE"""),"Cadet Scotty increases the Ship Hull Health by X.") -> Cadet Scotty increases the Ship Hull Health by X.
D28: =IFERROR(__xludf.DUMMYFUNCTION("""COMPUTED_VALUE""")," C") -> C | E28: =IFERROR(__xludf.DUMMYFUNCTION("""COMPUTED_VALUE"""),"CADET SULU") -> CADET SULU | F28: =IFERROR(__xludf.DUMMYFUNCTION("""COMPUTED_VALUE"""),"CM") -> CM | G28: =IFERROR(__xludf.DUMMYFUNCTION("""COMPUTED_VALUE"""),"✅") -> ✅ | I28: =IFERROR(__xludf.DUMMYFUNCTION("""COMPUTED_VALUE"""),"AllDamage") -> AllDamage | J28: =IFERROR(__xludf.DUMMYFUNCTION("""COMPUTED_VALUE"""),"Cadet Sulu increases the damage of the first shots of the ship by X for the first round.") -> Cadet Sulu increases the damage of the first shots of the ship by X for the first round.
D29: =IFERROR(__xludf.DUMMYFUNCTION("""COMPUTED_VALUE""")," C") -> C | E29: =IFERROR(__xludf.DUMMYFUNCTION("""COMPUTED_VALUE"""),"CADET SULU") -> CADET SULU | F29: =IFERROR(__xludf.DUMMYFUNCTION("""COMPUTED_VALUE"""),"OA") -> OA | G29: =IFERROR(__xludf.DUMMYFUNCTION("""COMPUTED_VALUE"""),"✅") -> ✅ | I29: =IFERROR(__xludf.DUMMYFUNCTION("""COMPUTED_VALUE"""),"OfficerStatAttack") -> OfficerStatAttack | J29: =IFERROR(__xludf.DUMMYFUNCTION("""COMPUTED_VALUE"""),"Cadet Sulu increases the Attack of all the Officers on the ship by X.") -> Cadet Sulu increases the Attack of all the Officers on the ship by X.
D30: =IFERROR(__xludf.DUMMYFUNCTION("""COMPUTED_VALUE""")," C") -> C | E30: =IFERROR(__xludf.DUMMYFUNCTION("""COMPUTED_VALUE"""),"CADET UHURA") -> CADET UHURA | F30: =IFERROR(__xludf.DUMMYFUNCTION("""COMPUTED_VALUE"""),"CM") -> CM | G30: =IFERROR(__xludf.DUMMYFUNCTION("""COMPUTED_VALUE"""),"✅") -> ✅ | I30: =IFERROR(__xludf.DUMMYFUNCTION("""COMPUTED_VALUE"""),"AllDamage") -> AllDamage | J30: =IFERROR(__xludf.DUMMYFUNCTION("""COMPUTED_VALUE"""),"Cadet Uhura decreases the Weapon Damage of the opponent's ship by X.") -> Cadet Uhura decreases the Weapon Damage of the opponent's ship by X.
D31: =IFERROR(__xludf.DUMMYFUNCTION("""COMPUTED_VALUE""")," C") -> C | E31: =IFERROR(__xludf.DUMMYFUNCTION("""COMPUTED_VALUE"""),"CADET UHURA") -> CADET UHURA | F31: =IFERROR(__xludf.DUMMYFUNCTION("""COMPUTED_VALUE"""),"OA") -> OA | G31: =IFERROR(__xludf.DUMMYFUNCTION("""COMPUTED_VALUE"""),"✅") -> ✅ | I31: =IFERROR(__xludf.DUMMYFUNCTION("""COMPUTED_VALUE"""),"ShieldHPMax") -> ShieldHPMax | J31: =IFERROR(__xludf.DUMMYFUNCTION("""COMPUTED_VALUE"""),"Cadet Uhura increases the Shield Health of the ship by X.") -> Cadet Uhura increases the Shield Health of the ship by X.
D32: =IFERROR(__xludf.DUMMYFUNCTION("""COMPUTED_VALUE""")," E") -> E | E32: =IFERROR(__xludf.DUMMYFUNCTION("""COMPUTED_VALUE"""),"CAROL") -> CAROL | F32: =IFERROR(__xludf.DUMMYFUNCTION("""COMPUTED_VALUE"""),"CM") -> CM | G32: =IFERROR(__xludf.DUMMYFUNCTION("""COMPUTED_VALUE"""),"✅") -> ✅ | I32: =IFERROR(__xludf.DUMMYFUNCTION("""COMPUTED_VALUE"""),"AllDamage") -> AllDamage | J32: =IFERROR(__xludf.DUMMYFUNCTION("""COMPUTED_VALUE"""),"When defending in battle against a player, Carol decreases the Weapon Damage from opponents by X.") -> When defending in battle against a player, Carol decreases the Weapon Damage from opponents by X.
D33: =IFERROR(__xludf.DUMMYFUNCTION("""COMPUTED_VALUE""")," E") -> E | E33: =IFERROR(__xludf.DUMMYFUNCTION("""COMPUTED_VALUE"""),"CAROL") -> CAROL | F33: =IFERROR(__xludf.DUMMYFUNCTION("""COMPUTED_VALUE"""),"OA") -> OA | G33: =IFERROR(__xludf.DUMMYFUNCTION("""COMPUTED_VALUE"""),"✅") -> ✅ | I33: =IFERROR(__xludf.DUMMYFUNCTION("""COMPUTED_VALUE"""),"AllDamage") -> AllDamage | J33: =IFERROR(__xludf.DUMMYFUNCTION("""COMPUTED_VALUE"""),"Carol increases the Weapon Damage by X.") -> Carol increases the Weapon Damage by X.
D34: =IFERROR(__xludf.DUMMYFUNCTION("""COMPUTED_VALUE""")," E") -> E | E34: =IFERROR(__xludf.DUMMYFUNCTION("""COMPUTED_VALUE"""),"CAROL FREEMAN") -> CAROL FREEMAN | F34: =IFERROR(__xludf.DUMMYFUNCTION("""COMPUTED_VALUE"""),"CM") -> CM | G34: =IFERROR(__xludf.DUMMYFUNCTION("""COMPUTED_VALUE"""),"✅") -> ✅ | I34: =IFERROR(__xludf.DUMMYFUNCTION("""COMPUTED_VALUE"""),"ShotsPerAttack") -> ShotsPerAttack | J34: =IFERROR(__xludf.DUMMYFUNCTION("""COMPUTED_VALUE"""),"On combat start against players, Carol Freeman increases your shots by X.") -> On combat start against players, Carol Freeman increases your shots by X.
D35: =IFERROR(__xludf.DUMMYFUNCTION("""COMPUTED_VALUE""")," E") -> E | E35: =IFERROR(__xludf.DUMMYFUNCTION("""COMPUTED_VALUE"""),"CHARVANEK") -> CHARVANEK | F35: =IFERROR(__xludf.DUMMYFUNCTION("""COMPUTED_VALUE"""),"OA") -> OA | G35: =IFERROR(__xludf.DUMMYFUNCTION("""COMPUTED_VALUE"""),"✅") -> ✅ | I35: =IFERROR(__xludf.DUMMYFUNCTION("""COMPUTED_VALUE"""),"ArmorPiercing") -> ArmorPiercing | J35: =IFERROR(__xludf.DUMMYFUNCTION("""COMPUTED_VALUE"""),"At the start of combat, Charvanek increases the Armor Piercing of the ship by X of the Health of the crew on the ship.") -> At the start of combat, Charvanek increases the Armor Piercing of the ship by X of the Health of the crew on the ship.
D36: =IFERROR(__xludf.DUMMYFUNCTION("""COMPUTED_VALUE""")," U") -> U | E36: =IFERROR(__xludf.DUMMYFUNCTION("""COMPUTED_VALUE"""),"D'JAOKI") -> D'JAOKI | F36: =IFERROR(__xludf.DUMMYFUNCTION("""COMPUTED_VALUE"""),"CM") -> CM | G36: =IFERROR(__xludf.DUMMYFUNCTION("""COMPUTED_VALUE"""),"✅") -> ✅ | I36: =IFERROR(__xludf.DUMMYFUNCTION("""COMPUTED_VALUE"""),"OfficerStatHealth") -> OfficerStatHealth | J36: =IFERROR(__xludf.DUMMYFUNCTION("""COMPUTED_VALUE"""),"After winning a combat, D'jaoki increases the Health of all officers on the ship by X for 1 minute.") -> After winning a combat, D'jaoki increases the Health of all officers on the ship by X for 1 minute.
D37: =IFERROR(__xludf.DUMMYFUNCTION("""COMPUTED_VALUE""")," E") -> E | E37: =IFERROR(__xludf.DUMMYFUNCTION("""COMPUTED_VALUE"""),"D'VANA TENDI") -> D'VANA TENDI | F37: =IFERROR(__xludf.DUMMYFUNCTION("""COMPUTED_VALUE"""),"OA") -> OA | G37: =IFERROR(__xludf.DUMMYFUNCTION("""COMPUTED_VALUE"""),"✅") -> ✅ | I37: =IFERROR(__xludf.DUMMYFUNCTION("""COMPUTED_VALUE"""),"OfficerStatHealth") -> OfficerStatHealth | J37: =IFERROR(__xludf.DUMMYFUNCTION("""COMPUTED_VALUE"""),"D'Vana Tendi increases the Health of all Officers on the ship by X.") -> D'Vana Tendi increases the Health of all Officers on the ship by X.
D38: =IFERROR(__xludf.DUMMYFUNCTION("""COMPUTED_VALUE""")," E") -> E | E38: =IFERROR(__xludf.DUMMYFUNCTION("""COMPUTED_VALUE"""),"D'VANA TENDI") -> D'VANA TENDI | F38: =IFERROR(__xludf.DUMMYFUNCTION("""COMPUTED_VALUE"""),"BDA") -> BDA | G38: =IFERROR(__xludf.DUMMYFUNCTION("""COMPUTED_VALUE"""),"✅") -> ✅ | I38: =IFERROR(__xludf.DUMMYFUNCTION("""COMPUTED_VALUE"""),"HullHPMax") -> HullHPMax | J38: =IFERROR(__xludf.DUMMYFUNCTION("""COMPUTED_VALUE"""),"D'Vana Tendi increases the ship's Hull Health by X.") -> D'Vana Tendi increases the ship's Hull Health by X.
D39: =IFERROR(__xludf.DUMMYFUNCTION("""COMPUTED_VALUE""")," C") -> C | E39: =IFERROR(__xludf.DUMMYFUNCTION("""COMPUTED_VALUE"""),"DARWIN") -> DARWIN | F39: =IFERROR(__xludf.DUMMYFUNCTION("""COMPUTED_VALUE"""),"CM") -> CM | G39: =IFERROR(__xludf.DUMMYFUNCTION("""COMPUTED_VALUE"""),"✅") -> ✅ | I39: =IFERROR(__xludf.DUMMYFUNCTION("""COMPUTED_VALUE"""),"AllDamage") -> AllDamage | J39: =IFERROR(__xludf.DUMMYFUNCTION("""COMPUTED_VALUE"""),"When the ship is attacked by a player, Darwin increases the Weapon Damage by X.") -> When the ship is attacked by a player, Darwin increases the Weapon Damage by X.
D40: =IFERROR(__xludf.DUMMYFUNCTION("""COMPUTED_VALUE""")," R") -> R | E40: =IFERROR(__xludf.DUMMYFUNCTION("""COMPUTED_VALUE"""),"DECIUS") -> DECIUS | F40: =IFERROR(__xludf.DUMMYFUNCTION("""COMPUTED_VALUE"""),"OA") -> OA | G40: =IFERROR(__xludf.DUMMYFUNCTION("""COMPUTED_VALUE"""),"✅") -> ✅ | I40: =IFERROR(__xludf.DUMMYFUNCTION("""COMPUTED_VALUE"""),"AllDamage") -> AllDamage | J40: =IFERROR(__xludf.DUMMYFUNCTION("""COMPUTED_VALUE"""),"Every time the ship gets hit by a weapon attack, Decius increases its Weapon Damage by X. -- (Weapons with multiple shots will only trigger this ability once per attack.)") -> Every time the ship gets hit by a weapon attack, Decius increases its Weapon Damage by X. -- (Weapons with multiple shots will only trigger this ability once per attack.)
D41: =IFERROR(__xludf.DUMMYFUNCTION("""COMPUTED_VALUE""")," E") -> E | E41: =IFERROR(__xludf.DUMMYFUNCTION("""COMPUTED_VALUE"""),"DOCTOR T'ANA") -> DOCTOR T'ANA | F41: =IFERROR(__xludf.DUMMYFUNCTION("""COMPUTED_VALUE"""),"OA") -> OA | G41: =IFERROR(__xludf.DUMMYFUNCTION("""COMPUTED_VALUE"""),"✅") -> ✅ | I41: =IFERROR(__xludf.DUMMYFUNCTION("""COMPUTED_VALUE"""),"AddRandomState") -> AddRandomState | J41: =IFERROR(__xludf.DUMMYFUNCTION("""COMPUTED_VALUE"""),"On round start, Dr. T'Ana has X chance to apply a random State to the enemy player's ship for 3 rounds. -- Random States: Morale, Burning, Hull Breach") -> On round start, Dr. T'Ana has X chance to apply a random State to the enemy player's ship for 3 rounds. -- Random States: Morale, Burning, Hull Breach
D42: =IFERROR(__xludf.DUMMYFUNCTION("""COMPUTED_VALUE""")," E") -> E | E42: =IFERROR(__xludf.DUMMYFUNCTION("""COMPUTED_VALUE"""),"DOCTOR T'ANA") -> DOCTOR T'ANA | F42: =IFERROR(__xludf.DUMMYFUNCTION("""COMPUTED_VALUE"""),"BDA") -> BDA | G42: =IFERROR(__xludf.DUMMYFUNCTION("""COMPUTED_VALUE"""),"✅") -> ✅ | I42: =IFERROR(__xludf.DUMMYFUNCTION("""COMPUTED_VALUE"""),"IsolyticDefense") -> IsolyticDefense | J42: =IFERROR(__xludf.DUMMYFUNCTION("""COMPUTED_VALUE"""),"On round start against players, Dr. T'Ana increases your Isolytic Defense by X for 1 round.") -> On round start against players, Dr. T'Ana increases your Isolytic Defense by X for 1 round.
D43: =IFERROR(__xludf.DUMMYFUNCTION("""COMPUTED_VALUE""")," U") -> U | E43: =IFERROR(__xludf.DUMMYFUNCTION("""COMPUTED_VALUE"""),"EIGHT OF ELEVEN") -> EIGHT OF ELEVEN | F43: =IFERROR(__xludf.DUMMYFUNCTION("""COMPUTED_VALUE"""),"OA") -> OA | G43: =IFERROR(__xludf.DUMMYFUNCTION("""COMPUTED_VALUE"""),"✅") -> ✅ | I43: =IFERROR(__xludf.DUMMYFUNCTION("""COMPUTED_VALUE"""),"OfficerStatAttack") -> OfficerStatAttack | J43: =IFERROR(__xludf.DUMMYFUNCTION("""COMPUTED_VALUE"""),"Eight of Eleven increases the Attack of every Officer on the ship by X.") -> Eight of Eleven increases the Attack of every Officer on the ship by X.
...

Sheet CT&FT - Search 
G2: ='Infos - Start Here!'!G2 -> 1.4-RC M86 | H2: =CONCATENATE("RC - Release Candidate",REPT(" · β",200)) -> RC - Release Candidate · β · β · β · β · β · β · β · β · β · β · β · β · β · β · β · β · β · β · β · β · β · β · β · β · β · β · β · β · β · β · β · β · β · β · β · β · β · β · β · β · β · β · β · β · β · β · β · β · β · β · β · β · β · β · β · β · β · β · β · β · β · β · β · β · β · β · β · β · β · β · β · β · β · β · β · β · β · β · β · β · β · β · β · β · β · β · β · β · β · β · β · β · β · β · β · β · β · β · β · β · β · β · β · β · β · β · β · β · β · β · β · β · β · β · β · β · β · β · β · β · β · β · β · β · β · β · β · β · β · β · β · β · β · β · β · β · β · β · β · β · β · β · β · β · β · β · β · β · β · β · β · β · β · β · β · β · β · β · β · β · β · β · β · β · β · β · β · β · β · β · β · β · β · β · β · β · β · β · β · β · β · β · β · β · β · β · β · β · β · β · β · β · β · β · β · β · β · β · β · β
D4: ᐅ | E4: Outpost Retaliation Attackers | H4: Select the Target | J4: Sort Order: Works, Name, Ability #
D5: ᐅ | E5: CT - Chaos Tech | H5: Switch between FT or CT
D6: ᐅ | H6: Search term e.g Hull Breach, Attack, State,…
D8: =IFERROR(__xludf.DUMMYFUNCTION("Query( FILTER( FILTER(LCARS_Tech[#ALL] , CONDITION_ONE_OF_RANGE( LCARS_Tech[#HEADERS] , settings[Minimum]) +(LCARS_Tech[#HEADERS] = E4) ), ISNUMBER(SEARCH( E6, LCARS_Tech[[#ALL],[Ability Description]])) + (LCARS_Tech[[#ALL],[BuffID]]=""BuffID""), (LCARS_T"&"ech[[#ALL],[TechType]] = LEFT(E5, 2))+(LCARS_Tech[[#ALL],[BuffID]]=""BuffID"") ) , ""SELECT * WHERE Col4 != '➖' ORDER BY Col4, Col2, Col3"",1 )")," Rarity") -> Rarity | E8: =IFERROR(__xludf.DUMMYFUNCTION("""COMPUTED_VALUE"""),"TechName") -> TechName | H8: =IFERROR(__xludf.DUMMYFUNCTION("""COMPUTED_VALUE"""),"Reason") -> Reason | I8: =IFERROR(__xludf.DUMMYFUNCTION("""COMPUTED_VALUE"""),"Ability Modifier") -> Ability Modifier | J8: =IFERROR(__xludf.DUMMYFUNCTION("""COMPUTED_VALUE"""),"Ability Description") -> Ability Description
D9: =IFERROR(__xludf.DUMMYFUNCTION("""COMPUTED_VALUE""")," E") -> E | E9: =IFERROR(__xludf.DUMMYFUNCTION("""COMPUTED_VALUE"""),"C-12 Stasis Globe") -> C-12 Stasis Globe | F9: =IFERROR(__xludf.DUMMYFUNCTION("""COMPUTED_VALUE"""),3.0) -> 3 | G9: =IFERROR(__xludf.DUMMYFUNCTION("""COMPUTED_VALUE"""),"✅") -> ✅ | I9: =IFERROR(__xludf.DUMMYFUNCTION("""COMPUTED_VALUE"""),"HullHPMax") -> HullHPMax | J9: =IFERROR(__xludf.DUMMYFUNCTION("""COMPUTED_VALUE"""),"Increases base HHP by X.") -> Increases base HHP by X.
D10: =IFERROR(__xludf.DUMMYFUNCTION("""COMPUTED_VALUE""")," R") -> R | E10: =IFERROR(__xludf.DUMMYFUNCTION("""COMPUTED_VALUE"""),"Genesis Device") -> Genesis Device | F10: =IFERROR(__xludf.DUMMYFUNCTION("""COMPUTED_VALUE"""),3.0) -> 3 | G10: =IFERROR(__xludf.DUMMYFUNCTION("""COMPUTED_VALUE"""),"✅") -> ✅ | I10: =IFERROR(__xludf.DUMMYFUNCTION("""COMPUTED_VALUE"""),"ShieldHPMax") -> ShieldHPMax | J10: =IFERROR(__xludf.DUMMYFUNCTION("""COMPUTED_VALUE"""),"Increases base SHP by X.") -> Increases base SHP by X.
D11: =IFERROR(__xludf.DUMMYFUNCTION("""COMPUTED_VALUE""")," R") -> R | E11: =IFERROR(__xludf.DUMMYFUNCTION("""COMPUTED_VALUE"""),"Mark VI Photon Torpedo") -> Mark VI Photon Torpedo | F11: =IFERROR(__xludf.DUMMYFUNCTION("""COMPUTED_VALUE"""),3.0) -> 3 | G11: =IFERROR(__xludf.DUMMYFUNCTION("""COMPUTED_VALUE"""),"✅") -> ✅ | I11: =IFERROR(__xludf.DUMMYFUNCTION("""COMPUTED_VALUE"""),"HullHPMax") -> HullHPMax | J11: =IFERROR(__xludf.DUMMYFUNCTION("""COMPUTED_VALUE"""),"Increases base Hull Health by X.") -> Increases base Hull Health by X.
D12: =IFERROR(__xludf.DUMMYFUNCTION("""COMPUTED_VALUE""")," R") -> R | E12: =IFERROR(__xludf.DUMMYFUNCTION("""COMPUTED_VALUE"""),"Omega Molecule") -> Omega Molecule | F12: =IFERROR(__xludf.DUMMYFUNCTION("""COMPUTED_VALUE"""),3.0) -> 3 | G12: =IFERROR(__xludf.DUMMYFUNCTION("""COMPUTED_VALUE"""),"✅") -> ✅ | I12: =IFERROR(__xludf.DUMMYFUNCTION("""COMPUTED_VALUE"""),"CritDamage") -> CritDamage | J12: =IFERROR(__xludf.DUMMYFUNCTION("""COMPUTED_VALUE"""),"Increases base Crit Damage for all ships by X.") -> Increases base Crit Damage for all ships by X.
D13: =IFERROR(__xludf.DUMMYFUNCTION("""COMPUTED_VALUE""")," E") -> E | E13: =IFERROR(__xludf.DUMMYFUNCTION("""COMPUTED_VALUE"""),"The Godsend") -> The Godsend | F13: =IFERROR(__xludf.DUMMYFUNCTION("""COMPUTED_VALUE"""),1.0) -> 1 | G13: =IFERROR(__xludf.DUMMYFUNCTION("""COMPUTED_VALUE"""),"✅") -> ✅ | I13: =IFERROR(__xludf.DUMMYFUNCTION("""COMPUTED_VALUE"""),"AllDamage") -> AllDamage | J13: =IFERROR(__xludf.DUMMYFUNCTION("""COMPUTED_VALUE"""),"Increases base Weapon Damage against hostiles by X.") -> Increases base Weapon Damage against hostiles by X.
D14: =IFERROR(__xludf.DUMMYFUNCTION("""COMPUTED_VALUE""")," R") -> R | E14: =IFERROR(__xludf.DUMMYFUNCTION("""COMPUTED_VALUE"""),"Tothian Mines") -> Tothian Mines | F14: =IFERROR(__xludf.DUMMYFUNCTION("""COMPUTED_VALUE"""),1.0) -> 1 | G14: =IFERROR(__xludf.DUMMYFUNCTION("""COMPUTED_VALUE"""),"✅") -> ✅ | I14: =IFERROR(__xludf.DUMMYFUNCTION("""COMPUTED_VALUE"""),"IsolyticDefense") -> IsolyticDefense | J14: =IFERROR(__xludf.DUMMYFUNCTION("""COMPUTED_VALUE"""),"Increases Isolytic Defense by X for 2 rounds when hit by a Critical Hit.") -> Increases Isolytic Defense by X for 2 rounds when hit by a Critical Hit.
D15: =IFERROR(__xludf.DUMMYFUNCTION("""COMPUTED_VALUE""")," E") -> E | E15: =IFERROR(__xludf.DUMMYFUNCTION("""COMPUTED_VALUE"""),"Echo Papa 607") -> Echo Papa 607 | F15: =IFERROR(__xludf.DUMMYFUNCTION("""COMPUTED_VALUE"""),1.0) -> 1 | G15: =IFERROR(__xludf.DUMMYFUNCTION("""COMPUTED_VALUE"""),"✴️") -> ✴️ | H15: =IFERROR(__xludf.DUMMYFUNCTION("""COMPUTED_VALUE"""),"HullHealthBelow") -> HullHealthBelow | I15: =IFERROR(__xludf.DUMMYFUNCTION("""COMPUTED_VALUE"""),"AllDamage") -> AllDamage | J15: =IFERROR(__xludf.DUMMYFUNCTION("""COMPUTED_VALUE"""),"Increases Weapon Damage by X when enemy HHP is below 40%.") -> Increases Weapon Damage by X when enemy HHP is below 40%.
D16: =IFERROR(__xludf.DUMMYFUNCTION("""COMPUTED_VALUE""")," R") -> R | E16: =IFERROR(__xludf.DUMMYFUNCTION("""COMPUTED_VALUE"""),"Particle Synthesis") -> Particle Synthesis | F16: =IFERROR(__xludf.DUMMYFUNCTION("""COMPUTED_VALUE"""),2.0) -> 2 | G16: =IFERROR(__xludf.DUMMYFUNCTION("""COMPUTED_VALUE"""),"✴️") -> ✴️ | H16: =IFERROR(__xludf.DUMMYFUNCTION("""COMPUTED_VALUE"""),"CombatPveRewards (on Serene Squall)") -> CombatPveRewards (on Serene Squall) | I16: =IFERROR(__xludf.DUMMYFUNCTION("""COMPUTED_VALUE"""),"CombatPveRewards") -> CombatPveRewards | J16: =IFERROR(__xludf.DUMMYFUNCTION("""COMPUTED_VALUE"""),"Increases loot from all Hostiles, Armadas or Outposts when using Serene Squall by X.") -> Increases loot from all Hostiles, Armadas or Outposts when using Serene Squall by X.
B22: ='Infos - Start Here!'!B22
B69: ='Infos - Start Here!'!B67
B116: ='Infos - Start Here!'!B114
B208: ='Infos - Start Here!'!B206
B282: ='Infos - Start Here!'!B280
D298: =CONCATENATE("RC - Release Candidate",REPT(" · β",200)) -> RC - Release Candidate · β · β · β · β · β · β · β · β · β · β · β · β · β · β · β · β · β · β · β · β · β · β · β · β · β · β · β · β · β · β · β · β · β · β · β · β · β · β · β · β · β · β · β · β · β · β · β · β · β · β · β · β · β · β · β · β · β · β · β · β · β · β · β · β · β · β · β · β · β · β · β · β · β · β · β · β · β · β · β · β · β · β · β · β · β · β · β · β · β · β · β · β · β · β · β · β · β · β · β · β · β · β · β · β · β · β · β · β · β · β · β · β · β · β · β · β · β · β · β · β · β · β · β · β · β · β · β · β · β · β · β · β · β · β · β · β · β · β · β · β · β · β · β · β · β · β · β · β · β · β · β · β · β · β · β · β · β · β · β · β · β · β · β · β · β · β · β · β · β · β · β · β · β · β · β · β · β · β · β · β · β · β · β · β · β · β · β · β · β · β · β · β · β · β · β · β · β · β · β · β

Sheet Officers Compact
D2: =IFERROR(__xludf.DUMMYFUNCTION("FILTER(LCARS_Off[#ALL] , CONDITION_ONE_OF_RANGE( LCARS_Off[#HEADERS] , settings[Short]))")," Rarity") -> Rarity | E2: =IFERROR(__xludf.DUMMYFUNCTION("""COMPUTED_VALUE"""),"OfficerName") -> OfficerName | G2: =IFERROR(__xludf.DUMMYFUNCTION("""COMPUTED_VALUE"""),"PvP Space") -> PvP Space | H2: =IFERROR(__xludf.DUMMYFUNCTION("""COMPUTED_VALUE"""),"PvP Station") -> PvP Station | I2: =IFERROR(__xludf.DUMMYFUNCTION("""COMPUTED_VALUE"""),"Red Moving Space") -> Red Moving Space | J2: =IFERROR(__xludf.DUMMYFUNCTION("""COMPUTED_VALUE"""),"Waves") -> Waves | K2: =IFERROR(__xludf.DUMMYFUNCTION("""COMPUTED_VALUE"""),"QTrial") -> QTrial | L2: =IFERROR(__xludf.DUMMYFUNCTION("""COMPUTED_VALUE"""),"Mission Bosses") -> Mission Bosses | M2: =IFERROR(__xludf.DUMMYFUNCTION("""COMPUTED_VALUE"""),"Group Armadas") -> Group Armadas | N2: =IFERROR(__xludf.DUMMYFUNCTION("""COMPUTED_VALUE"""),"Solo Armadas") -> Solo Armadas | O2: =IFERROR(__xludf.DUMMYFUNCTION("""COMPUTED_VALUE"""),"Invading Entities") -> Invading Entities | P2: =IFERROR(__xludf.DUMMYFUNCTION("""COMPUTED_VALUE"""),"Assaults") -> Assaults | Q2: =IFERROR(__xludf.DUMMYFUNCTION("""COMPUTED_VALUE"""),"Outpost Armadas") -> Outpost Armadas | R2: =IFERROR(__xludf.DUMMYFUNCTION("""COMPUTED_VALUE"""),"Outpost Retaliation Attackers") -> Outpost Retaliation Attackers | S2: =IFERROR(__xludf.DUMMYFUNCTION("""COMPUTED_VALUE"""),"Reason") -> Reason | T2: =IFERROR(__xludf.DUMMYFUNCTION("""COMPUTED_VALUE"""),"Loot") -> Loot | U2: =IFERROR(__xludf.DUMMYFUNCTION("""COMPUTED_VALUE"""),"Utility") -> Utility
D3: =IFERROR(__xludf.DUMMYFUNCTION("""COMPUTED_VALUE""")," E") -> E | E3: =IFERROR(__xludf.DUMMYFUNCTION("""COMPUTED_VALUE"""),"KIRK") -> KIRK | F3: =IFERROR(__xludf.DUMMYFUNCTION("""COMPUTED_VALUE"""),"CM") -> CM | G3: =IFERROR(__xludf.DUMMYFUNCTION("""COMPUTED_VALUE"""),"✴️") -> ✴️ | H3: =IFERROR(__xludf.DUMMYFUNCTION("""COMPUTED_VALUE"""),"✴️") -> ✴️ | I3: =IFERROR(__xludf.DUMMYFUNCTION("""COMPUTED_VALUE"""),"✴️") -> ✴️ | J3: =IFERROR(__xludf.DUMMYFUNCTION("""COMPUTED_VALUE"""),"✴️") -> ✴️ | K3: =IFERROR(__xludf.DUMMYFUNCTION("""COMPUTED_VALUE"""),"✴️") -> ✴️ | L3: =IFERROR(__xludf.DUMMYFUNCTION("""COMPUTED_VALUE"""),"✴️") -> ✴️ | M3: =IFERROR(__xludf.DUMMYFUNCTION("""COMPUTED_VALUE"""),"✴️") -> ✴️ | N3: =IFERROR(__xludf.DUMMYFUNCTION("""COMPUTED_VALUE"""),"✴️") -> ✴️ | ... Q3: =IFERROR(__xludf.DUMMYFUNCTION("""COMPUTED_VALUE"""),"✴️") -> ✴️ | R3: =IFERROR(__xludf.DUMMYFUNCTION("""COMPUTED_VALUE""")," ✴️") -> ✴️ | S3: =IFERROR(__xludf.DUMMYFUNCTION("""COMPUTED_VALUE"""),"SelfHasMorale") -> SelfHasMorale | T3: =IFERROR(__xludf.DUMMYFUNCTION("""COMPUTED_VALUE"""),"➖") -> ➖ | U3: =IFERROR(__xludf.DUMMYFUNCTION("""COMPUTED_VALUE"""),"➖") -> ➖
D4: =IFERROR(__xludf.DUMMYFUNCTION("""COMPUTED_VALUE""")," E") -> E | E4: =IFERROR(__xludf.DUMMYFUNCTION("""COMPUTED_VALUE"""),"KIRK") -> KIRK | F4: =IFERROR(__xludf.DUMMYFUNCTION("""COMPUTED_VALUE"""),"OA") -> OA | G4: =IFERROR(__xludf.DUMMYFUNCTION("""COMPUTED_VALUE"""),"✅") -> ✅ | H4: =IFERROR(__xludf.DUMMYFUNCTION("""COMPUTED_VALUE"""),"✅") -> ✅ | I4: =IFERROR(__xludf.DUMMYFUNCTION("""COMPUTED_VALUE"""),"✅") -> ✅ | J4: =IFERROR(__xludf.DUMMYFUNCTION("""COMPUTED_VALUE"""),"✅") -> ✅ | K4: =IFERROR(__xludf.DUMMYFUNCTION("""COMPUTED_VALUE"""),"✅") -> ✅ | L4: =IFERROR(__xludf.DUMMYFUNCTION("""COMPUTED_VALUE"""),"✅") -> ✅ | M4: =IFERROR(__xludf.DUMMYFUNCTION("""COMPUTED_VALUE"""),"✅") -> ✅ | N4: =IFERROR(__xludf.DUMMYFUNCTION("""COMPUTED_VALUE"""),"✅") -> ✅ | ... Q4: =IFERROR(__xludf.DUMMYFUNCTION("""COMPUTED_VALUE"""),"✅") -> ✅ | R4: =IFERROR(__xludf.DUMMYFUNCTION("""COMPUTED_VALUE""")," ✅") -> ✅ | T4: =IFERROR(__xludf.DUMMYFUNCTION("""COMPUTED_VALUE"""),"➖") -> ➖ | U4: =IFERROR(__xludf.DUMMYFUNCTION("""COMPUTED_VALUE"""),"➖") -> ➖
D5: =IFERROR(__xludf.DUMMYFUNCTION("""COMPUTED_VALUE""")," R") -> R | E5: =IFERROR(__xludf.DUMMYFUNCTION("""COMPUTED_VALUE"""),"SPOCK") -> SPOCK | F5: =IFERROR(__xludf.DUMMYFUNCTION("""COMPUTED_VALUE"""),"CM") -> CM | G5: =IFERROR(__xludf.DUMMYFUNCTION("""COMPUTED_VALUE"""),"✅") -> ✅ | H5: =IFERROR(__xludf.DUMMYFUNCTION("""COMPUTED_VALUE"""),"✅") -> ✅ | I5: =IFERROR(__xludf.DUMMYFUNCTION("""COMPUTED_VALUE"""),"✅") -> ✅ | J5: =IFERROR(__xludf.DUMMYFUNCTION("""COMPUTED_VALUE"""),"✅") -> ✅ | K5: =IFERROR(__xludf.DUMMYFUNCTION("""COMPUTED_VALUE"""),"✅") -> ✅ | L5: =IFERROR(__xludf.DUMMYFUNCTION("""COMPUTED_VALUE"""),"✅") -> ✅ | M5: =IFERROR(__xludf.DUMMYFUNCTION("""COMPUTED_VALUE"""),"✅") -> ✅ | N5: =IFERROR(__xludf.DUMMYFUNCTION("""COMPUTED_VALUE"""),"✅") -> ✅ | ... Q5: =IFERROR(__xludf.DUMMYFUNCTION("""COMPUTED_VALUE"""),"✅") -> ✅ | R5: =IFERROR(__xludf.DUMMYFUNCTION("""COMPUTED_VALUE""")," ✅") -> ✅ | T5: =IFERROR(__xludf.DUMMYFUNCTION("""COMPUTED_VALUE"""),"➖") -> ➖ | U5: =IFERROR(__xludf.DUMMYFUNCTION("""COMPUTED_VALUE"""),"➖") -> ➖
D6: =IFERROR(__xludf.DUMMYFUNCTION("""COMPUTED_VALUE""")," R") -> R | E6: =IFERROR(__xludf.DUMMYFUNCTION("""COMPUTED_VALUE"""),"SPOCK") -> SPOCK | F6: =IFERROR(__xludf.DUMMYFUNCTION("""COMPUTED_VALUE"""),"OA") -> OA | G6: =IFERROR(__xludf.DUMMYFUNCTION("""COMPUTED_VALUE"""),"✴️") -> ✴️ | H6: =IFERROR(__xludf.DUMMYFUNCTION("""COMPUTED_VALUE"""),"✴️") -> ✴️ | I6: =IFERROR(__xludf.DUMMYFUNCTION("""COMPUTED_VALUE"""),"✴️") -> ✴️ | J6: =IFERROR(__xludf.DUMMYFUNCTION("""COMPUTED_VALUE"""),"✴️") -> ✴️ | K6: =IFERROR(__xludf.DUMMYFUNCTION("""COMPUTED_VALUE"""),"✴️") -> ✴️ | L6: =IFERROR(__xludf.DUMMYFUNCTION("""COMPUTED_VALUE"""),"✴️") -> ✴️ | M6: =IFERROR(__xludf.DUMMYFUNCTION("""COMPUTED_VALUE"""),"✴️") -> ✴️ | N6: =IFERROR(__xludf.DUMMYFUNCTION("""COMPUTED_VALUE"""),"✴️") -> ✴️ | ... Q6: =IFERROR(__xludf.DUMMYFUNCTION("""COMPUTED_VALUE"""),"✴️") -> ✴️ | R6: =IFERROR(__xludf.DUMMYFUNCTION("""COMPUTED_VALUE""")," ✴️") -> ✴️ | S6: =IFERROR(__xludf.DUMMYFUNCTION("""COMPUTED_VALUE"""),"SelfHasMorale") -> SelfHasMorale | T6: =IFERROR(__xludf.DUMMYFUNCTION("""COMPUTED_VALUE"""),"➖") -> ➖ | U6: =IFERROR(__xludf.DUMMYFUNCTION("""COMPUTED_VALUE"""),"➖") -> ➖
D7: =IFERROR(__xludf.DUMMYFUNCTION("""COMPUTED_VALUE""")," R") -> R | E7: =IFERROR(__xludf.DUMMYFUNCTION("""COMPUTED_VALUE"""),"BONES") -> BONES | F7: =IFERROR(__xludf.DUMMYFUNCTION("""COMPUTED_VALUE"""),"CM") -> CM | G7: =IFERROR(__xludf.DUMMYFUNCTION("""COMPUTED_VALUE"""),"✴️") -> ✴️ | H7: =IFERROR(__xludf.DUMMYFUNCTION("""COMPUTED_VALUE"""),"✴️") -> ✴️ | I7: =IFERROR(__xludf.DUMMYFUNCTION("""COMPUTED_VALUE"""),"✴️") -> ✴️ | J7: =IFERROR(__xludf.DUMMYFUNCTION("""COMPUTED_VALUE"""),"✴️") -> ✴️ | K7: =IFERROR(__xludf.DUMMYFUNCTION("""COMPUTED_VALUE"""),"✴️") -> ✴️ | L7: =IFERROR(__xludf.DUMMYFUNCTION("""COMPUTED_VALUE"""),"✴️") -> ✴️ | M7: =IFERROR(__xludf.DUMMYFUNCTION("""COMPUTED_VALUE"""),"✴️") -> ✴️ | N7: =IFERROR(__xludf.DUMMYFUNCTION("""COMPUTED_VALUE"""),"✴️") -> ✴️ | ... Q7: =IFERROR(__xludf.DUMMYFUNCTION("""COMPUTED_VALUE"""),"✴️") -> ✴️ | R7: =IFERROR(__xludf.DUMMYFUNCTION("""COMPUTED_VALUE""")," ✴️") -> ✴️ | S7: =IFERROR(__xludf.DUMMYFUNCTION("""COMPUTED_VALUE"""),"target level 70 or under") -> target level 70 or under | T7: =IFERROR(__xludf.DUMMYFUNCTION("""COMPUTED_VALUE"""),"➖") -> ➖ | U7: =IFERROR(__xludf.DUMMYFUNCTION("""COMPUTED_VALUE"""),"➖") -> ➖
